<?xml version="1.0"?>
<robot xmlns:xacro="http://www.ros.org/wiki/xacro">

    <xacro:include filename="inertial_macros.xacro"/>

    <!-- Materials -->
    <material name="white">
        <color rgba="1 1 1 1"/>
    </material>

    <material name="black">
        <color rgba="0 0 0 1"/>
    </material>

    <material name="blue">
        <color rgba="0.2 0.2 1 1"/>
    </material>

    <!-- Base Link -->
    <link name="base_link"/>

    <joint name="base_footprint_joint" type="fixed">
        <parent link="base_link"/>
        <child link="base_footprint"/>
        <origin xyz="0 0 0" rpy="0 0 0"/>
    </joint>

    <link name="base_footprint"/>

    <!-- Chassis -->
    <joint name="chassis_joint" type="fixed">
        <parent link="base_link"/>
        <child link="chassis"/>
        <origin xyz="0 0 0" rpy="0 0 0"/>
    </joint>

    <link name="chassis">
        <visual>
            <origin xyz="0 0 0.15"/>
            <geometry>
                <box size="0.6 0.4 0.1"/>
            </geometry>
            <material name="white"/>
        </visual>
        <collision>
            <origin xyz="0 0 0.15"/>
            <geometry>
                <box size="0.6 0.4 0.1"/>
            </geometry>
        </collision>
        <inertial>
            <mass value="1.5"/>
            <origin xyz="0 0 0.15"/>
            <inertia ixx="0.02" iyy="0.02" izz="0.02" ixy="0" ixz="0" iyz="0"/>
        </inertial>
    </link>

    <!-- Steering Wheel -->
    <joint name="steering_wheel_joint" type="revolute">
        <parent link="chassis"/>
        <child link="steering_wheel"/>
        <origin xyz="0 0 0.25" rpy="0 0 0"/>
        <axis xyz="0 1 0"/>
        <limit effort="5.0" velocity="2.0" lower="-0.75" upper="0.75"/>
    </joint>

    <link name="steering_wheel">
        <visual>
            <origin xyz="0 0 0"/>
            <geometry>
                <cylinder radius="0.15" length="0.02"/>
            </geometry>
            <material name="black"/>
        </visual>
    </link>

    <!-- Rear Left Wheel -->
    <joint name="rear_left_wheel_joint" type="continuous">
        <parent link="chassis"/>
        <child link="rear_left_wheel"/>
        <origin xyz="-0.25 0.225 0.1" rpy="1.57 0 0"/>
        <axis xyz="0 0 -1"/>
    </joint>

    <link name="rear_left_wheel">
        <visual>
            <geometry>
                <cylinder radius="0.1" length="0.05"/>
            </geometry>
            <material name="blue"/>
        </visual>
        <collision>
            <geometry>
                <cylinder radius="0.1" length="0.05"/>
            </geometry>
        </collision>
        <inertial>
            <mass value="0.1"/>
            <inertia ixx="0.001" iyy="0.001" izz="0.001" ixy="0" ixz="0" iyz="0"/>
        </inertial>
    </link>

    <!-- Rear Right Wheel -->
    <joint name="rear_right_wheel_joint" type="continuous">
        <parent link="chassis"/>
        <child link="rear_right_wheel"/>
        <origin xyz="-0.25 -0.225 0.1" rpy="1.57 0 0"/>
        <axis xyz="0 0 -1"/>
    </joint>

    <link name="rear_right_wheel">
        <visual>
            <geometry>
                <cylinder radius="0.1" length="0.05"/>
            </geometry>
            <material name="blue"/>
        </visual>
        <collision>
            <geometry>
                <cylinder radius="0.1" length="0.05"/>
            </geometry>
        </collision>
        <inertial>
            <mass value="0.1"/>
            <inertia ixx="0.001" iyy="0.001" izz="0.001" ixy="0" ixz="0" iyz="0"/>
        </inertial>
    </link>

    <!-- Front Left Steering Mechanism -->
    <joint name="front_left_wheel_steer_joint" type="revolute">
        <parent link="chassis"/>
        <child link="front_left_wheel_steer"/>
        <origin xyz="0.25 0.225 0.1" rpy="0 0 0"/>
        <axis xyz="0 0 1"/>
        <limit effort="10.0" velocity="1.0" lower="-0.5" upper="0.5"/>
    </joint>

    <link name="front_left_wheel_steer">
        <visual>
            <geometry>
                <box size="0.01 0.01 0.01"/>
            </geometry>
            <material name="black"/>
        </visual>
    </link>

    <joint name="front_left_wheel_joint" type="continuous">
        <parent link="front_left_wheel_steer"/>
        <child link="front_left_wheel"/>
        <origin xyz="0 0 0" rpy="1.57 0 0"/>
        <axis xyz="0 0 -1"/>
    </joint>

    <link name="front_left_wheel">
        <visual>
            <geometry>
                <cylinder radius="0.1" length="0.05"/>
            </geometry>
            <material name="blue"/>
        </visual>
        <collision>
            <geometry>
                <cylinder radius="0.1" length="0.05"/>
            </geometry>
        </collision>
        <inertial>
            <mass value="0.1"/>
            <inertia ixx="0.001" iyy="0.001" izz="0.001" ixy="0" ixz="0" iyz="0"/>
        </inertial>
    </link>

    <!-- Front Right Steering Mechanism -->
    <joint name="front_right_wheel_steer_joint" type="revolute">
        <parent link="chassis"/>
        <child link="front_right_wheel_steer"/>
        <origin xyz="0.25 -0.225 0.1" rpy="0 0 0"/>
        <axis xyz="0 0 1"/>
        <limit effort="10.0" velocity="1.0" lower="-0.5" upper="0.5"/>
    </joint>

    <link name="front_right_wheel_steer">
        <visual>
            <geometry>
                <box size="0.01 0.01 0.01"/>
            </geometry>
            <material name="black"/>
        </visual>
    </link>

    <joint name="front_right_wheel_joint" type="continuous">
        <parent link="front_right_wheel_steer"/>
        <child link="front_right_wheel"/>
        <origin xyz="0 0 0" rpy="1.57 0 0"/>
        <axis xyz="0 0 -1"/>
    </joint>

    <link name="front_right_wheel">
        <visual>
            <geometry>
                <cylinder radius="0.1" length="0.05"/>
            </geometry>
            <material name="blue"/>
        </visual>
    </link>

</robot>
